Workbook

Sheet gameModeMap_header
A1: Index | B1: Key | C1: Value | D1: DirectlyImport? | E1: Flexible | F1: OutputOrder
A2: 0 | B2: key | C2: 主键 | D2: √ | F2: 0
A3: 1 | B3: mModeName | C3: 模式代号 | D3: √ | F3: 1
A4: 2 | B4: Configs | C4: 模式基础信息目录 | D4: √ | E4: √ | F4: 4
A5: 3 | B5: ConfigsClient | C5: 客户端配置目录 | D5: √ | F5: 5
A6: 4 | B6: mChampionLists | C6: 英雄列表 | D6: √ | E6: √ | F6: 11
A7: 5 | B7: itemLists | C7: 装备目录 | D7: √ | F7: 13
A8: 6 | B8: {dc2bc473} | C8: 模式特定装备目录 | D8: √ | E8: √ | F8: 14
A9: 7 | B9: mItemShopData | C9: 商店数据 | D9: √ | F9: 12
A10: 8 | B10: AdditionalPropertyDataPaths | C10: 附加说明文件路径 | D10: √ | F10: 28
A11: 9 | B11: AnnouncementsMapping | C11: 通告映射 | D11: √ | F11: 22
A12: 10 | B12: mRelativeColorization | C12: 采用相对着色法 | D12: √ | F12: 23
A13: 11 | B13: mCursorConfig | C13: 指针配置文件 | D13: √ | F13: 25
A14: 12 | B14: mCursorConfigUpdate | C14: 新版指针配置文件 | D14: √ | F14: 26
A15: 13 | B15: mStatsUiData | C15: 属性面板数据 | D15: √ | F15: 10
A16: 14 | B16: mChampionIndicatorEnabled | C16: 英雄指示器可用性 | D16: √ | E16: √ | F16: 24
A17: 15 | B17: JungleRecommendationMapInformation | C17: 推荐打野路线信息 | D17: √ | E17: √ | F17: 18
A18: 16 | B18: DefaultJunglePathRecommendation | C18: 默认打野路线 | D18: √ | E18: √ | F18: 19
A19: 17 | B19: StartupCheats | C19: 启动指令 | D19: √ | E19: √ | F19: 9
A20: 18 | B20: mExperienceCurveData | C20: 经验曲线算法 | D20: √ | F20: 6
A21: 19 | B21: mExperienceModData | C21: 经验获取调整 | D21: √ | F21: 7
A22: 20 | B22: mDeathTimes | C22: 复活计时器 | D22: √ | F22: 8
A23: 21 | B23: mMapLocators | C23: 地图物件坐标 | D23: √ | F23: 16
A24: 22 | B24: mPerkReplacements | C24: 符文替换信息 | D24: √ | E24: √ | F24: 20
A25: 23 | B25: mGameModeConstants | C25: 游戏模式常数 | D25: √ | F25: 2
A26: 24 | B26: DefaultRespawnPoints | C26: 默认重生位置 | D26: √ | E26: √ | F26: 17
A27: 25 | B27: mGameplayConfig | C27: 游戏玩法信息 | D27: √ | F27: 3
A28: 26 | B28: mSurrenderSettings | C28: 投降设置 | D28: √ | F28: 21
A29: 27 | B29: mAutoItemPurchasingConfig | C29: 装备构件购买信息 | D29: √ | F29: 15
A30: 28 | B30: LevelControllers | C30: 荣誉等级管理 | D30: √ | E30: √ | F30: 27
A31: 29 | B31: Configs SmartPingData {5aa830e8} | D31: √
A32: 30 | B32: Configs SmartPingData {aa8eb438} | D32: √
A33: 31 | B33: Configs SmartPingData {1e98bb0e} | D33: √
A34: 32 | B34: Configs CharacterQuestListConfig {6f7129e6} | D34: √
A35: 33 | B35: Configs CharacterQuestListConfig {702d99a3} | D35: √
A36: 34 | B36: Configs CharacterQuestListConfig CharacterQuestList | C36: 英雄彩蛋列表 | D36: √
A37: 35 | B37: Configs CharacterQuestListConfig CharacterQuestDefinitionsList | C37: 英雄彩蛋定义 | D37: √
A38: 36 | B38: Configs ReciprocityConfig throttleLimit | D38: √
A39: 37 | B39: Configs ReciprocityConfig {8e26fcb2} | D39: √
A40: 38 | B40: Configs {6b91544a} BlurTextures | C40: 启用模糊纹理 | D40: √
...

Sheet cheatset_header
A1: Index | B1: Key | C1: Value | D1: DirectlyImport? | E1: Flexible | F1: defaultValue | G1: OutputOrder
A2: 0 | B2: key | C2: 主键 | D2: √ | G2: 0
A3: 1 | B3: mName | C3: 代码 | D3: √ | G3: 1
A4: 2 | B4: mIsPlayerFacing | C4: 可见性 | D4: √ | E4: √ | G4: 2
A5: 3 | B5: mGameModeName | C5: 游戏模式 | D5: √ | E5: √ | G5: 4
A6: 4 | B6: mGameMutator | C6: 子模式 | D6: √ | E6: √ | G6: 5
A7: 5 | B7: AssociatedChampions | C7: 相关英雄 | D7: √ | E7: √ | G7: 6
A8: 6 | B8: {bd50bdef} | C8: 指令列表 | D8: √ | E8: √ | G8: 7
A9: 7 | B9: mIsUIAlwaysShown | C9: 总是呈现 | D9: √ | E9: √ | G9: 3

Sheet cheat_header
A1: Index | B1: Key | C1: Value | D1: DirectlyImport? | E1: Flexible | F1: defaultValue | G1: OutputOrder
A2: 0 | B2: key | C2: 主键 | D2: √ | G2: 0
A3: 1 | B3: mName | C3: 代码 | D3: √ | G3: 3
A4: 2 | B4: mIsPlayerFacing | C4: 可见性 | D4: √ | E4: √ | F4: FALSE | G4: 5
A5: 3 | B5: mRecastFrequency | C5: 施法频率 | D5: √ | E5: √ | G5: 19
A6: 4 | B6: mTarget | C6: 作用目标 | D6: √ | E6: √ | G6: 20
A7: 5 | B7: UseTargetAsCaster | C7: 目标作为施法者 | D7: √ | E7: √ | F7: FALSE | G7: 21
A8: 6 | B8: UseTargetAsSource | C8: 目标作为来源 | D8: √ | E8: √ | F8: FALSE | G8: 22
A9: 7 | B9: mTimerValue | C9: 计时器取值 | D9: √ | E9: √ | G9: 23
A10: 8 | B10: mDamageAmount | C10: 伤害数额（百分比） | D10: √ | G10: 24
A11: 9 | B11: mScriptCallback | C11: 调用方法 | D11: √ | G11: 7
A12: 10 | B12: {30ce16ae} | C12: 作用野怪类型 | D12: √ | G12: 25
A13: 11 | B13: mKillExistingMinions | C13: 击杀存活小兵 | D13: √ | E13: √ | F13: FALSE | G13: 26
A14: 12 | B14: mKillWards | C14: 摧毁守卫 | D14: √ | E14: √ | F14: FALSE | G14: 27
A15: 13 | B15: mStartingItemIds | C15: 起始装备序号列表 | D15: √ | G15: 28
A16: 14 | B16: mGoldAmount | C16: 金币数额 | D16: √ | G16: 29
A17: 15 | B17: mFlags | C17: 旗标 | D17: √ | G17: 30
A18: 16 | B18: mTeam | C18: 阵营代号 | D18: √ | G18: 31
A19: 17 | B19: mPlayerName | C19: 玩家代码 | D19: √ | G19: 32
A20: 18 | B20: mMinionName | C20: 小兵代码 | D20: √ | G20: 33
A21: 19 | B21: mCharacterName | C21: 角色名称 | D21: √ | G21: 34
A22: 20 | B22: mAmount | C22: 数额 | D22: √ | G22: 35
A23: 21 | B23: mSpeedDown | C23: 减速 | D23: √ | E23: √ | F23: FALSE | G23: 36
A24: 22 | B24: mSpeedUp | C24: 加速 | D24: √ | E24: √ | F24: FALSE | G24: 37
A25: 23 | B25: ResetToBaseSpeed | C25: 重置为基础移动速度 | D25: √ | F25: FALSE | G25: 38
A26: 24 | B26: MoveDelta | C26: 移动速度增量 | D26: √ | G26: 39
A27: 25 | B27: mToggleHP | C27: 启用/禁用生命回复 | D27: √ | E27: √ | F27: FALSE | G27: 40
A28: 26 | B28: mTogglePAR | C28: 启用/禁用施法资源回复 | D28: √ | E28: √ | F28: FALSE | G28: 41
A29: 27 | B29: mGiveMaxLevel | C29: 提供最大等级 | D29: √ | G29: 42
A30: 28 | B30: mOnlyOnePointEach | C30: 即点即杀 | D30: √ | F30: FALSE | G30: 43
A31: 29 | B31: __type | C31: 对象数据类型 | D31: √ | G31: 1
A32: 30 | B32: mDisplayName | C32: 显示名 | G32: 4
A33: 31 | B33: mFloatingTextDisplayName | C33: 标题键 | D33: √ | E33: √ | G33: 8
A34: 32 | B34: mTooltipText | C34: 说明键 | D34: √ | E34: √ | G34: 11
A35: 33 | B35: mDynamicTooltipText | C35: 详细信息键 | D35: √ | E35: √ | G35: 14
A36: 34 | B36: mHotkey | C36: 快捷键代码 | D36: √ | E36: √ | G36: 17
A37: 35 | B37: mHotkeys | C37: 可用快捷键代码 | D37: √ | E37: √ | G37: 18
A38: 36 | B38: mIsToggleCheat | C38: 开关型 | D38: √ | E38: √ | F38: FALSE | G38: 6
A39: 37 | B39: mCheatMenuUIDataType | C39: 指令菜单数据类型 | D39: √ | E39: √
A40: 38 | B40: mFloatingTextDisplayName_content_zh | C40: 标题（中文） | E40: √ | G40: 9
...

Sheet spell_header
A1: Index | B1: Key | C1: Value | D1: DirectlyImport? | E1: Flexible | F1: defaultValue | G1: OutputOrder
A2: 0 | B2: key | C2: 主键 | D2: √ | G2: 0
A3: 1 | B3: ObjectName | C3: 指令对象名称 | D3: √ | G3: 1
A4: 2 | B4: mScriptName | C4: 脚本名称 | D4: √ | G4: 7
A5: 3 | B5: {34cdd819} | D5: √ | E5: √ | G5: 2
A6: 4 | B6: Script | C6: 脚本主键 | D6: √ | E6: √ | G6: 6
A7: 5 | B7: mSpell flags | C7: 指令旗标 | D7: √ | E7: √ | G7: 9
A8: 6 | B8: mSpell mAffectsTypeFlags | C8: 作用目标类型旗标 | D8: √ | E8: √ | G8: 10
A9: 7 | B9: mSpell mAffectsStatusFlags | C9: 作用状态旗标 | D9: √ | E9: √ | G9: 11
A10: 8 | B10: mSpell mRequiredUnitTags mObjectTagList | C10: 所需目标单位标签列表 | D10: √ | G10: 71
A11: 9 | B11: mSpell mExcludedUnitTags mObjectTagList | C11: 无效目标单位标签列表 | D11: √ | G11: 72
A12: 10 | B12: mSpell mPlatformSpellInfo mAvatarLevelRequired | C12: 展现化身所需等级 | D12: √ | E12: √ | G12: 75
A13: 11 | B13: mSpell mPlatformSpellInfo mSpellID | C13: 指令序号 | D13: √ | E13: √ | G13: 74
A14: 12 | B14: mSpell mPlatformSpellInfo mPlatformEnabled | C14: 可用性 | D14: √ | E14: √ | F14: FALSE | G14: 76
A15: 13 | B15: mSpell mPlatformSpellInfo mGameModes | C15: 适用游戏模式 | D15: √ | E15: √ | G15: 77
A16: 14 | B16: mSpell mCastRequirementsCaster | C16: 施法条件 | D16: √ | E16: √ | G16: 67
A17: 15 | B17: mSpell mCastRequirementsTarget | C17: 施法目标条件 | D17: √ | E17: √ | G17: 68
A18: 16 | B18: mSpell mAlternateName | C18: 指令别名 | D18: √ | E18: √ | G18: 8
A19: 17 | B19: mSpell mSpellTags | C19: 指令标签 | D19: √ | E19: √ | G19: 12
A20: 18 | B20: mSpell mEffectAmount | C20: 效应因子 | D20: √ | E20: √ | G20: 33
A21: 19 | B21: mSpell DataValues | C21: 数值 | D21: √ | E21: √ | G21: 34
A22: 20 | B22: mSpell DataValuesModeOverride | C22: 模式覆盖数值 | D22: √ | E22: √ | G22: 35
A23: 21 | B23: mSpell {b08bc498} | C23: 模式覆盖基础充能时间 | D23: √ | E23: √ | G23: 30
A24: 22 | B24: mSpell {f9c2333e} | C24: 模式覆盖基础冷却时间 | D24: √ | E24: √ | G24: 23
A25: 23 | B25: mSpell mSpellCalculations | C25: 数值计算 | D25: √ | E25: √ | G25: 36
A26: 24 | B26: mSpell mCoefficient | C26: 系数1 | D26: √ | E26: √ | G26: 38
... A33: 31 | B33: mSpell mKeywordWhenAcquired | C33: 获得技能时的关键字 | D33: √ | E33: √ | G33: 78
A34: 32 | B34: mSpell PassiveSpellAffectedByCooldown | C34: 被动技能冷却时间受技能急速影响 | D34: √ | E34: √ | F34: FALSE | G34: 24
A35: 33 | B35: mSpell ImgIconPath | C35: 缩略图路径 | D35: √ | E35: √ | G35: 242
A36: 34 | B36: mSpell mMinimapIconName | C36: 小地图缩略图路径 | D36: √ | E36: √ | G36: 244
A37: 35 | B37: mSpell mCastTime | C37: 施法时间 | D37: √ | E37: √ | G37: 52
A38: 36 | B38: mSpell {11704a2b} | D38: √ | G38: 83
A39: 37 | B39: mSpell {f26881a0} | D39: √ | G39: 84
A40: 38 | B40: mSpell mChannelDuration | C40: 引导持续时间 | D40: √ | E40: √ | G40: 53
A41: 39 | B41: mSpell cooldownTime | C41: 基础冷却时间 | D41: √ | E41: √ | G41: 20
A42: 40 | B42: mSpell Cooldown values | C42: 基础冷却时间值 | D42: √ | G42: 21
A43: 41 | B43: mSpell Cooldown {0a3e0478} | C43: 基础冷却时间值简化表示 | D43: √ | E43: √ | G43: 22
A44: 42 | B44: mSpell delayCastOffsetPercent | C44: 施法偏移百分比 | D44: √ | E44: √ | G44: 60
A45: 43 | B45: mSpell delayTotalTimePercent | C45: 施法总时间百分比 | D45: √ | E45: √ | G45: 61
A46: 44 | B46: mSpell mStartCooldown | C46: 冷却计时时间点 | D46: √ | E46: √ | G46: 26
...

Sheet summoner_spell_header
A1: Index | B1: Key | C1: Value | D1: DirectlyImport? | E1: Flexible | F1: defaultValue | G1: OutputOrder
A2: 0 | B2: key | C2: =_xlfn.LET(_xlpm.x,VLOOKUP($B2,spell_header!$B$2:$G$373,2,FALSE),IF(_xlpm.x="","",_xlpm.x)) -> 主键 | D2: =IF(VLOOKUP($B2,spell_header!$B$2:$G$373,3,FALSE)="√","√","") -> √ | E2: =IF(VLOOKUP($B2,spell_header!$B$2:$G$373,4,FALSE)="√","√","") | F2: =_xlfn.LET(_xlpm.x,VLOOKUP($B2,spell_header!$B$2:$G$373,5,FALSE),IF(_xlpm.x="","",_xlpm.x)) | G2: 0
A3: 1 | B3: ObjectName | C3: =_xlfn.LET(_xlpm.x,VLOOKUP($B3,spell_header!$B$2:$G$373,2,FALSE),IF(_xlpm.x="","",_xlpm.x)) -> 指令对象名称 | D3: =IF(VLOOKUP($B3,spell_header!$B$2:$G$373,3,FALSE)="√","√","") -> √ | E3: =IF(VLOOKUP($B3,spell_header!$B$2:$G$373,4,FALSE)="√","√","") | F3: =_xlfn.LET(_xlpm.x,VLOOKUP($B3,spell_header!$B$2:$G$373,5,FALSE),IF(_xlpm.x="","",_xlpm.x)) | G3: 1
A4: 2 | B4: mScriptName | C4: =_xlfn.LET(_xlpm.x,VLOOKUP($B4,spell_header!$B$2:$G$373,2,FALSE),IF(_xlpm.x="","",_xlpm.x)) -> 脚本名称 | D4: =IF(VLOOKUP($B4,spell_header!$B$2:$G$373,3,FALSE)="√","√","") -> √ | E4: =IF(VLOOKUP($B4,spell_header!$B$2:$G$373,4,FALSE)="√","√","") | F4: =_xlfn.LET(_xlpm.x,VLOOKUP($B4,spell_header!$B$2:$G$373,5,FALSE),IF(_xlpm.x="","",_xlpm.x)) | G4: 11
A5: 3 | B5: {34cdd819} | C5: =_xlfn.LET(_xlpm.x,VLOOKUP($B5,spell_header!$B$2:$G$373,2,FALSE),IF(_xlpm.x="","",_xlpm.x)) | D5: =IF(VLOOKUP($B5,spell_header!$B$2:$G$373,3,FALSE)="√","√","") -> √ | E5: =IF(VLOOKUP($B5,spell_header!$B$2:$G$373,4,FALSE)="√","√","") -> √ | F5: =_xlfn.LET(_xlpm.x,VLOOKUP($B5,spell_header!$B$2:$G$373,5,FALSE),IF(_xlpm.x="","",_xlpm.x)) | G5: 9
A6: 4 | B6: Script | C6: =_xlfn.LET(_xlpm.x,VLOOKUP($B6,spell_header!$B$2:$G$373,2,FALSE),IF(_xlpm.x="","",_xlpm.x)) -> 脚本主键 | D6: =IF(VLOOKUP($B6,spell_header!$B$2:$G$373,3,FALSE)="√","√","") -> √ | E6: =IF(VLOOKUP($B6,spell_header!$B$2:$G$373,4,FALSE)="√","√","") -> √ | F6: =_xlfn.LET(_xlpm.x,VLOOKUP($B6,spell_header!$B$2:$G$373,5,FALSE),IF(_xlpm.x="","",_xlpm.x)) | G6: 10
A7: 5 | B7: mSpell flags | C7: =_xlfn.LET(_xlpm.x,VLOOKUP($B7,spell_header!$B$2:$G$373,2,FALSE),IF(_xlpm.x="","",_xlpm.x)) -> 指令旗标 | D7: =IF(VLOOKUP($B7,spell_header!$B$2:$G$373,3,FALSE)="√","√","") -> √ | E7: =IF(VLOOKUP($B7,spell_header!$B$2:$G$373,4,FALSE)="√","√","") -> √ | F7: =_xlfn.LET(_xlpm.x,VLOOKUP($B7,spell_header!$B$2:$G$373,5,FALSE),IF(_xlpm.x="","",_xlpm.x)) | G7: 13
A8: 6 | B8: mSpell mAffectsTypeFlags | C8: =_xlfn.LET(_xlpm.x,VLOOKUP($B8,spell_header!$B$2:$G$373,2,FALSE),IF(_xlpm.x="","",_xlpm.x)) -> 作用目标类型旗标 | D8: =IF(VLOOKUP($B8,spell_header!$B$2:$G$373,3,FALSE)="√","√","") -> √ | E8: =IF(VLOOKUP($B8,spell_header!$B$2:$G$373,4,FALSE)="√","√","") -> √ | F8: =_xlfn.LET(_xlpm.x,VLOOKUP($B8,spell_header!$B$2:$G$373,5,FALSE),IF(_xlpm.x="","",_xlpm.x)) | G8: 14
A9: 7 | B9: mSpell mAffectsStatusFlags | C9: =_xlfn.LET(_xlpm.x,VLOOKUP($B9,spell_header!$B$2:$G$373,2,FALSE),IF(_xlpm.x="","",_xlpm.x)) -> 作用状态旗标 | D9: =IF(VLOOKUP($B9,spell_header!$B$2:$G$373,3,FALSE)="√","√","") -> √ | E9: =IF(VLOOKUP($B9,spell_header!$B$2:$G$373,4,FALSE)="√","√","") -> √ | F9: =_xlfn.LET(_xlpm.x,VLOOKUP($B9,spell_header!$B$2:$G$373,5,FALSE),IF(_xlpm.x="","",_xlpm.x)) | G9: 15
A10: 8 | B10: mSpell mRequiredUnitTags mObjectTagList | C10: =_xlfn.LET(_xlpm.x,VLOOKUP($B10,spell_header!$B$2:$G$373,2,FALSE),IF(_xlpm.x="","",_xlpm.x)) -> 所需目标单位标签列表 | D10: =IF(VLOOKUP($B10,spell_header!$B$2:$G$373,3,FALSE)="√","√","") -> √ | E10: =IF(VLOOKUP($B10,spell_header!$B$2:$G$373,4,FALSE)="√","√","") | F10: =_xlfn.LET(_xlpm.x,VLOOKUP($B10,spell_header!$B$2:$G$373,5,FALSE),IF(_xlpm.x="","",_xlpm.x)) | G10: 75
A11: 9 | B11: mSpell mExcludedUnitTags mObjectTagList | C11: =_xlfn.LET(_xlpm.x,VLOOKUP($B11,spell_header!$B$2:$G$373,2,FALSE),IF(_xlpm.x="","",_xlpm.x)) -> 无效目标单位标签列表 | D11: =IF(VLOOKUP($B11,spell_header!$B$2:$G$373,3,FALSE)="√","√","") -> √ | E11: =IF(VLOOKUP($B11,spell_header!$B$2:$G$373,4,FALSE)="√","√","") | F11: =_xlfn.LET(_xlpm.x,VLOOKUP($B11,spell_header!$B$2:$G$373,5,FALSE),IF(_xlpm.x="","",_xlpm.x)) | G11: 76
A12: 10 | B12: mSpell mPlatformSpellInfo mAvatarLevelRequired | C12: =_xlfn.LET(_xlpm.x,VLOOKUP($B12,spell_header!$B$2:$G$373,2,FALSE),IF(_xlpm.x="","",_xlpm.x)) -> 展现化身所需等级 | D12: =IF(VLOOKUP($B12,spell_header!$B$2:$G$373,3,FALSE)="√","√","") -> √ | E12: =IF(VLOOKUP($B12,spell_header!$B$2:$G$373,4,FALSE)="√","√","") -> √ | F12: =_xlfn.LET(_xlpm.x,VLOOKUP($B12,spell_header!$B$2:$G$373,5,FALSE),IF(_xlpm.x="","",_xlpm.x)) | G12: 7
A13: 11 | B13: mSpell mPlatformSpellInfo mSpellID | C13: =_xlfn.LET(_xlpm.x,VLOOKUP($B13,spell_header!$B$2:$G$373,2,FALSE),IF(_xlpm.x="","",_xlpm.x)) -> 指令序号 | D13: =IF(VLOOKUP($B13,spell_header!$B$2:$G$373,3,FALSE)="√","√","") -> √ | E13: =IF(VLOOKUP($B13,spell_header!$B$2:$G$373,4,FALSE)="√","√","") -> √ | F13: =_xlfn.LET(_xlpm.x,VLOOKUP($B13,spell_header!$B$2:$G$373,5,FALSE),IF(_xlpm.x="","",_xlpm.x)) | G13: 2
... A373: 371 | B373: BotData {591f8423} | C373: =_xlfn.LET(_xlpm.x,VLOOKUP($B373,spell_header!$B$2:$G$373,2,FALSE),IF(_xlpm.x="","",_xlpm.x)) | D373: =IF(VLOOKUP($B373,spell_header!$B$2:$G$373,3,FALSE)="√","√","") -> √ | E373: =IF(VLOOKUP($B373,spell_header!$B$2:$G$373,4,FALSE)="√","√","") -> √ | F373: =_xlfn.LET(_xlpm.x,VLOOKUP($B373,spell_header!$B$2:$G$373,5,FALSE),IF(_xlpm.x="","",_xlpm.x)) | G373: 371

Sheet perkstyle_header
A1: Index | B1: Key | C1: Value | D1: DirectlyImport? | E1: Flexible | F1: defaultValue | G1: OutputOrder
A2: 0 | B2: key | C2: 主键 | D2: √ | G2: 0
A3: 1 | B3: mPerkStyleId | C3: 符文系序号 | D3: √ | G3: 1
A4: 2 | B4: mPerkStyleName | C4: 符文系代码 | D4: √ | G4: 2
A5: 3 | B5: mDisplayNameLocalizationKey | C5: 显示名键 | D5: √ | G5: 3
A6: 4 | B6: mTooltipNameLocalizationKey | C6: 简介键 | D6: √ | G6: 7
A7: 5 | B7: mDefaultPageLocalizationKey | C7: 默认符文页名称键 | D7: √ | G7: 71
A8: 6 | B8: mIconTextureName | C8: 图标纹理名称 | D8: √ | G8: 80
A9: 7 | B9: mIsAdvancedStyle | C9: 高级符文系 | D9: √ | E9: √ | F9: FALSE | G9: 6
A10: 8 | B10: mAllowedSubStyles | C10: 可用副系序号 | D10: √ | G10: 10
A11: 9 | B11: mSubStyleBonus | C11: 副系加成 | D11: √ | G11: 13
A12: 10 | B12: mDefaultSplash mStyle | C12: 默认插画符文系 | D12: √ | G12: 81
A13: 11 | B13: mDefaultSplash mPerk1 | C13: 默认插画符文1 | D13: √ | G13: 82
A14: 12 | B14: mDefaultSplash mPerk2 | C14: 默认插画符文2 | D14: √ | G14: 83
A15: 13 | B15: mDefaultPerksWhenSplashed | C15: 渲染插画时默认使用符文 | D15: √ | G15: 74
A16: 14 | B16: mDefaultStatModsPerSubStyle | C16: 搭配各副系时的默认属性符文 | D16: √ | G16: 46
A17: 15 | B17: mSlots | C17: 槽位 | D17: √ | G17: 17
A18: 16 | B18: mSlotlinks | C18: 槽位主键 | D18: √ | G18: 14
A19: 17 | B19: mScript mSpellScriptName | C19: 指令名称 | D19: √ | G19: 77
A20: 18 | B20: mScript mSpellScriptData | C20: 指令数据 | D20: √ | E20: √ | G20: 78
A21: 19 | B21: mScriptAsSubStyle | C21: 用作副系时的指令 | D21: √ | G21: 79
A22: 20 | B22: mStyleVFXResourceResolver resourceMap | C22: 视觉效果资源解析器映射字典 | D22: √ | E22: √ | G22: 84
A23: 21 | B23: mDisplayNameLocalizationKey_content_zh | C23: 显示名（中文） | G23: 4
A24: 22 | B24: mDisplayNameLocalizationKey_content_en | C24: 显示名（英文） | G24: 5
A25: 23 | B25: mTooltipNameLocalizationKey_content_zh | C25: 简介（中文） | G25: 8
A26: 24 | B26: mTooltipNameLocalizationKey_content_en | C26: 简介（英文） | G26: 9
A27: 25 | B27: mDefaultPageLocalizationKey_content_zh | C27: 默认符文页名称（中文） | G27: 72
A28: 26 | B28: mDefaultPageLocalizationKey_content_en | C28: 默认符文页名称（英文） | G28: 73
A29: 27 | B29: mAllowedSubStyles mDisplayNameLocalizationKey_contents_zh | C29: 可用副系名称（中文） | G29: 11
A30: 28 | B30: mAllowedSubStyles mDisplayNameLocalizationKey_contents_en | C30: 可用副系名称（英文） | G30: 12
A31: 29 | B31: mDefaultPerksWhenSplashed mDisplayNameLocalizationKey_contents_zh | C31: 渲染插画时默认使用符文名称（中文） | G31: 75
A32: 30 | B32: mDefaultPerksWhenSplashed mDisplayNameLocalizationKey_contents_en | C32: 渲染插画时默认使用符文名称（英文） | G32: 76
A33: 31 | B33: mDefaultStatModsPerSubStyle1 mStyleId | C33: 搭配各副系时的默认属性符文：副系1序号 | G33: 47
A34: 32 | B34: mDefaultStatModsPerSubStyle1 mPerks | C34: 搭配各副系时的默认属性符文：副系1属性符文 | G34: 50
... A86: 84 | B86: mSlotlinks mSlotLabelKey_contents_en | C86: 槽位标签（英文） | G86: 16

Sheet perk_header
A1: Index | B1: Key | C1: Value | D1: DirectlyImport? | E1: Flexible | F1: defaultValue | G1: OutputOrder
A2: 0 | B2: key | C2: 主键 | D2: √ | G2: 0
A3: 1 | B3: mPerkId | C3: 符文序号 | D3: √ | G3: 1
A4: 2 | B4: mPerkName | C4: 符文代码 | D4: √ | G4: 2
A5: 3 | B5: mDisplayNameLocalizationKey | C5: 显示名键 | D5: √ | G5: 3
A6: 4 | B6: mTooltipNameLocalizationKey | C6: 简介键 | D6: √ | E6: √ | G6: 12
A7: 5 | B7: mPingTextLocalizationKey | C7: 标记文本键 | D7: √ | E7: √ | G7: 18
A8: 6 | B8: mShortDescLocalizationKey | C8: 简述键 | D8: √ | E8: √ | G8: 21
A9: 7 | B9: mLongDescLocalizationKey | C9: 详细信息键 | D9: √ | E9: √ | G9: 26
A10: 8 | B10: mEndOfGameStatDescriptions | C10: 赛后结算描述键 | D10: √ | E10: √ | G10: 31
A11: 9 | B11: mDisplayStatLocalizationKey | C11: 显示属性定位键 | D11: √ | E11: √ | G11: 17
A12: 10 | B12: mIconTextureName | C12: 图标纹理名称 | D12: √ | G12: 40
A13: 11 | B13: mStackable | C13: 可叠加 | D13: √ | E13: √ | F13: FALSE | G13: 10
A14: 12 | B14: mEnabled | C14: 可用性 | D14: √ | E14: √ | F14: TRUE | G14: 9
A15: 13 | B15: mScript mSpellScriptName | C15: 指令名称 | D15: √ | G15: 36
A16: 14 | B16: mScript mSpellScriptData | C16: 指令数据 | G16: 37
A17: 15 | B17: mBuffs | C17: 增益信息 | D17: √ | E17: √ | G17: 38
A18: 16 | B18: mVFXResourceResolver resourceMap | C18: 视觉效果资源解析器映射字典 | D18: √ | E18: √ | G18: 41
A19: 17 | B19: mSummonerPerkReplacements mReplacements | C19: 召唤师符文替换 | D19: √ | E19: √ | G19: 34
A20: 18 | B20: mDefault | C20: 默认符文 | D20: √ | E20: √ | F20: FALSE | G20: 11
A21: 19 | B21: mCharacters | C21: 相关角色 | D21: √ | E21: √ | G21: 35
A22: 20 | B22: mMajorChangePatchVersion | C22: 主要变更版本号 | D22: √ | E22: √ | G22: 39
A23: 21 | B23: mDisplayNameLocalizationKey_content_zh | C23: 显示名（中文） | G23: 4
A24: 22 | B24: mDisplayNameLocalizationKey_content_en | C24: 显示名（英文） | G24: 5
A25: 23 | B25: mTooltipNameLocalizationKey_content_zh | C25: 简介（中文） | G25: 13
A26: 24 | B26: mTooltipNameLocalizationKey_content_en | C26: 简介（英文） | G26: 15
A27: 25 | B27: mTooltipNameLocalizationKey_content_zh_burn | C27: 简介（中文/数值转换） | G27: 14
A28: 26 | B28: mTooltipNameLocalizationKey_content_en_burn | C28: 简介（英文/数值转换） | G28: 16
A29: 27 | B29: mPingTextLocalizationKey_content_zh | C29: 标记文本（中文） | G29: 19
A30: 28 | B30: mPingTextLocalizationKey_content_en | C30: 标记文本（英文） | G30: 20
A31: 29 | B31: mShortDescLocalizationKey_content_zh | C31: 简述（中文） | G31: 22
A32: 30 | B32: mShortDescLocalizationKey_content_en | C32: 简述（英文） | G32: 24
A33: 31 | B33: mShortDescLocalizationKey_content_zh_burn | C33: 简述（中文/数值转换） | G33: 23
A34: 32 | B34: mShortDescLocalizationKey_content_en_burn | C34: 简述（英文/数值转换） | G34: 25
... A40: 38 | B40: mEndOfGameStatDescriptions_contents_en | C40: 赛后结算描述（英文） | G40: 33
A41: 39 | B41: belonging_perkstyle_key | C41: 所属符文系主键
A42: 40 | B42: belonging_perkstyle mDisplayNameLocalizationKey_content_zh | C42: 所属符文系显示名（中文） | G42: 6
A43: 41 | B43: belonging_perkstyle mDisplayNameLocalizationKey_content_en | C43: 所属符文系显示名（英文） | G43: 7
A44: 42 | B44: belonging_perkstyle_slotIndex | C44: 所属符文系槽位序号 | G44: 8

Sheet champion_header
A1: Index | B1: Key | C1: Value | D1: DirectlyImport? | E1: Flexible1 | F1: Flexible2 | G1: defaultValue | H1: OutputOrder1 (champion; before v16.5) | I1: OutputOrder2 (character; before v16.5) | J1: OutputOrder3 (champion; after v16.5) | K1: OutputOrder4 (character; after v16.5)
A2: 0 | B2: key | C2: 主键 | D2: √ | H2: 0 | I2: 0 | J2: 0 | K2: 0
A3: 1 | B3: modeFolder | C3: 游戏模式文件夹 | E3: √ | F3: √ | H3: 1 | I3: 1 | J3: 1 | K3: 1
A4: 2 | B4: mCharacterName | C4: 角色名称 | D4: √ | H4: 2 | I4: 2 | J4: 2 | K4: 2
A5: 3 | B5: mFallbackCharacterName | C5: 备用名称 | D5: √ | E5: √ | F5: √ | H5: 6 | I5: 6 | J5: 6 | K5: 6
A6: 4 | B6: PackmanagerData | C6: 跟随者数据 | D6: √ | E6: √ | F6: √ | H6: 143 | I6: 143 | J6: 143 | K6: 143
A7: 5 | B7: {dd661aab} | C7: 冲刺配置 | D7: √ | E7: √ | F7: √ | H7: 192 | I7: 192 | J7: 192 | K7: 192
A8: 6 | B8: evolutionData | C8: 技能进化数据 | D8: √ | E8: √ | F8: √ | H8: 193 | I8: 193 | J8: 193 | K8: 193
A9: 7 | B9: useableData | C9: 可用数据 | D9: √ | F9: √ | H9: 157 | I9: 157 | J9: 157 | K9: 157
A10: 8 | B10: baseHP | C10: 基础生命值 | D10: √ | F10: √ | H10: 51 | I10: 51
A11: 9 | B11: hpPerLevel | C11: 成长生命值 | D11: √ | F11: √ | H11: 52 | I11: 52
A12: 10 | B12: baseStaticHPRegen | C12: 基础生命回复 | D12: √ | E12: √ | F12: √ | H12: 63 | I12: 63
A13: 11 | B13: hpRegenPerLevel | C13: 生命回复成长 | D13: √ | E13: √ | F13: √ | H13: 64 | I13: 64
A14: 12 | B14: highlightHealthbarIcons | C14: 高亮生命槽 | D14: √ | E14: √ | F14: √ | G14: FALSE | H14: 110 | I14: 110 | J14: 110 | K14: 110
A15: 13 | B15: healthBarHeight | C15: 血条高度 | D15: √ | E15: √ | F15: √ | H15: 115 | I15: 115 | J15: 115 | K15: 115
A16: 14 | B16: selfChampSpecificHealthSuffix | C16: 己方视角下的英雄生命槽颜色 | D16: √ | E16: √ | F16: √ | H16: 111 | I16: 111 | J16: 111 | K16: 111
A17: 15 | B17: selfCBChampSpecificHealthSuffix | C17: 己方色盲视角下的英雄生命槽颜色 | D17: √ | E17: √ | F17: √ | H17: 112 | I17: 112 | J17: 112 | K17: 112
A18: 16 | B18: allyChampSpecificHealthSuffix | C18: 友方视角下的英雄生命槽颜色 | D18: √ | E18: √ | F18: √ | H18: 113 | I18: 113 | J18: 113 | K18: 113
A19: 17 | B19: enemyChampSpecificHealthSuffix | C19: 敌方视角下的英雄生命槽颜色 | D19: √ | E19: √ | F19: √ | H19: 114 | I19: 114 | J19: 114 | K19: 114
A20: 18 | B20: healthBarFullParallax | C20: 生命槽使用完整视差效果 | D20: √ | F20: √ | G20: FALSE | H20: 116 | I20: 116 | J20: 116 | K20: 116
A21: 19 | B21: primaryAbilityResource | C21: 主要施法资源 | D21: √ | F21: √ | H21: 15 | I21: 15 | J21: 15 | K21: 15
A22: 20 | B22: secondaryAbilityResource | C22: 次要施法资源 | D22: √ | E22: √ | F22: √ | H22: 28 | I22: 28 | J22: 28 | K22: 28
A23: 21 | B23: baseDamage | C23: 基础攻击力 | D23: √ | F23: √ | H23: 53 | I23: 53
A24: 22 | B24: damagePerLevel | C24: 成长攻击力 | D24: √ | E24: √ | F24: √ | H24: 54 | I24: 54
A25: 23 | B25: baseArmor | C25: 基础护甲 | D25: √ | F25: √ | H25: 55 | I25: 55
A26: 24 | B26: armorPerLevel | C26: 成长护甲 | D26: √ | E26: √ | F26: √ | H26: 56 | I26: 56
A27: 25 | B27: critPerLevel | C27: 成长暴击几率 | D27: √ | F27: √ | H27: 67 | I27: 67 | J27: 67 | K27: 67
A28: 26 | B28: baseSpellBlock | C28: 基础魔法抗性 | D28: √ | F28: √ | H28: 57 | I28: 57
A29: 27 | B29: baseCritChance | C29: 基础暴击几率 | D29: √ | F29: √ | H29: 66 | I29: 66 | J29: 66 | K29: 66
A30: 28 | B30: spellBlockPerLevel | C30: 成长魔法抗性 | D30: √ | E30: √ | F30: √ | H30: 58 | I30: 58
A31: 29 | B31: critDamageMultiplier | C31: 暴击伤害修正率 | D31: √ | E31: √ | F31: √ | H31: 68 | I31: 68 | J31: 68 | K31: 68
A32: 30 | B32: baseMoveSpeed | C32: 基础移动速度 | D32: √ | F32: √ | H32: 62 | I32: 62
A33: 31 | B33: RotationSmoothing | C33: 模型旋转平滑度 | D33: √ | F33: √ | H33: 141 | I33: 141 | J33: 141 | K33: 141
A34: 32 | B34: attackRange | C34: 攻击距离 | D34: √ | F34: √ | H34: 65 | I34: 65
A35: 33 | B35: attackSpeed | C35: 基础攻击速度 | D35: √ | F35: √ | H35: 59 | I35: 59
A36: 34 | B36: attackSpeedRatio | C36: 攻击速度收益率 | D36: √ | F36: √ | H36: 61 | I36: 61
A37: 35 | B37: attackSpeedPerLevel | C37: 成长攻击速度 | D37: √ | E37: √ | F37: √ | H37: 60 | I37: 60
A38: 36 | B38: TreatAutoAttacksAsNormalSpells | C38: 自动攻击视为技能配置 | D38: √ | E38: √ | F38: √ | H38: 137 | I38: 137 | J38: 137 | K38: 137
A39: 37 | B39: mAdaptiveForceToAbilityPowerWeight | C39: 适应之力转法强比例 | D39: √ | E39: √ | F39: √ | H39: 69 | I39: 69 | J39: 69 | K39: 69
A40: 38 | B40: acquisitionRange | C40: 索敌范围半径 | D40: √ | E40: √ | F40: √ | H40: 121 | I40: 121 | J40: 121 | K40: 121
...

Sheet champion_spell_header
A1: Index | B1: Key | C1: Value | D1: DirectlyImport? | E1: Flexible | F1: defaultValue | G1: OutputOrder
A2: 0 | B2: mCharacterName | C2: 角色名称 | G2: 2
A3: 1 | B3: isRootSpell | C3: 根技能 | G3: 8
A4: 2 | B4: rootAbility_key | C4: 所属技能键 | D4: √ | G4: 7
A5: 3 | B5: rootAbility_mLifetimeManuallyManaged | C5: 所属技能的持续时间可控制 | E5: √ | F5: FALSE | G5: 12
A6: 4 | B6: rootAbility_mName | C6: 所属技能名称 | G6: 9
A7: 5 | B7: rootAbility_mType | C7: 所属技能类型 | E7: √ | G7: 10
A8: 6 | B8: rootAbility_AbilityTraits | C8: 所属技能特征旗标 | E8: √ | G8: 11
A9: 7 | B9: spellHotKey | C9: 技能热键 | G9: 3
A10: 8 | B10: key | C10: =_xlfn.LET(_xlpm.x,VLOOKUP($B10,spell_header!$B$2:$G$373,2,FALSE),IF(_xlpm.x="","",_xlpm.x)) -> 主键 | D10: =IF(VLOOKUP($B10,spell_header!$B$2:$G$373,3,FALSE)="√","√","") -> √ | E10: =IF(VLOOKUP($B10,spell_header!$B$2:$G$373,4,FALSE)="√","√","") | F10: =_xlfn.LET(_xlpm.x,VLOOKUP($B10,spell_header!$B$2:$G$373,5,FALSE),IF(_xlpm.x="","",_xlpm.x)) | G10: 0
A11: 9 | B11: ObjectName | C11: =_xlfn.LET(_xlpm.x,VLOOKUP($B11,spell_header!$B$2:$G$373,2,FALSE),IF(_xlpm.x="","",_xlpm.x)) -> 指令对象名称 | D11: =IF(VLOOKUP($B11,spell_header!$B$2:$G$373,3,FALSE)="√","√","") -> √ | E11: =IF(VLOOKUP($B11,spell_header!$B$2:$G$373,4,FALSE)="√","√","") | F11: =_xlfn.LET(_xlpm.x,VLOOKUP($B11,spell_header!$B$2:$G$373,5,FALSE),IF(_xlpm.x="","",_xlpm.x)) | G11: 1
A12: 10 | B12: mScriptName | C12: =_xlfn.LET(_xlpm.x,VLOOKUP($B12,spell_header!$B$2:$G$373,2,FALSE),IF(_xlpm.x="","",_xlpm.x)) -> 脚本名称 | D12: =IF(VLOOKUP($B12,spell_header!$B$2:$G$373,3,FALSE)="√","√","") -> √ | E12: =IF(VLOOKUP($B12,spell_header!$B$2:$G$373,4,FALSE)="√","√","") | F12: =_xlfn.LET(_xlpm.x,VLOOKUP($B12,spell_header!$B$2:$G$373,5,FALSE),IF(_xlpm.x="","",_xlpm.x)) | G12: 15
A13: 11 | B13: {34cdd819} | C13: =_xlfn.LET(_xlpm.x,VLOOKUP($B13,spell_header!$B$2:$G$373,2,FALSE),IF(_xlpm.x="","",_xlpm.x)) | D13: =IF(VLOOKUP($B13,spell_header!$B$2:$G$373,3,FALSE)="√","√","") -> √ | E13: =IF(VLOOKUP($B13,spell_header!$B$2:$G$373,4,FALSE)="√","√","") -> √ | F13: =_xlfn.LET(_xlpm.x,VLOOKUP($B13,spell_header!$B$2:$G$373,5,FALSE),IF(_xlpm.x="","",_xlpm.x)) | G13: 13
A14: 12 | B14: Script | C14: =_xlfn.LET(_xlpm.x,VLOOKUP($B14,spell_header!$B$2:$G$373,2,FALSE),IF(_xlpm.x="","",_xlpm.x)) -> 脚本主键 | D14: =IF(VLOOKUP($B14,spell_header!$B$2:$G$373,3,FALSE)="√","√","") -> √ | E14: =IF(VLOOKUP($B14,spell_header!$B$2:$G$373,4,FALSE)="√","√","") -> √ | F14: =_xlfn.LET(_xlpm.x,VLOOKUP($B14,spell_header!$B$2:$G$373,5,FALSE),IF(_xlpm.x="","",_xlpm.x)) | G14: 14
A15: 13 | B15: mSpell flags | C15: =_xlfn.LET(_xlpm.x,VLOOKUP($B15,spell_header!$B$2:$G$373,2,FALSE),IF(_xlpm.x="","",_xlpm.x)) -> 指令旗标 | D15: =IF(VLOOKUP($B15,spell_header!$B$2:$G$373,3,FALSE)="√","√","") -> √ | E15: =IF(VLOOKUP($B15,spell_header!$B$2:$G$373,4,FALSE)="√","√","") -> √ | F15: =_xlfn.LET(_xlpm.x,VLOOKUP($B15,spell_header!$B$2:$G$373,5,FALSE),IF(_xlpm.x="","",_xlpm.x)) | G15: 17
A16: 14 | B16: mSpell mAffectsTypeFlags | C16: =_xlfn.LET(_xlpm.x,VLOOKUP($B16,spell_header!$B$2:$G$373,2,FALSE),IF(_xlpm.x="","",_xlpm.x)) -> 作用目标类型旗标 | D16: =IF(VLOOKUP($B16,spell_header!$B$2:$G$373,3,FALSE)="√","√","") -> √ | E16: =IF(VLOOKUP($B16,spell_header!$B$2:$G$373,4,FALSE)="√","√","") -> √ | F16: =_xlfn.LET(_xlpm.x,VLOOKUP($B16,spell_header!$B$2:$G$373,5,FALSE),IF(_xlpm.x="","",_xlpm.x)) | G16: 18
A17: 15 | B17: mSpell mAffectsStatusFlags | C17: =_xlfn.LET(_xlpm.x,VLOOKUP($B17,spell_header!$B$2:$G$373,2,FALSE),IF(_xlpm.x="","",_xlpm.x)) -> 作用状态旗标 | D17: =IF(VLOOKUP($B17,spell_header!$B$2:$G$373,3,FALSE)="√","√","") -> √ | E17: =IF(VLOOKUP($B17,spell_header!$B$2:$G$373,4,FALSE)="√","√","") -> √ | F17: =_xlfn.LET(_xlpm.x,VLOOKUP($B17,spell_header!$B$2:$G$373,5,FALSE),IF(_xlpm.x="","",_xlpm.x)) | G17: 19
A18: 16 | B18: mSpell mRequiredUnitTags mObjectTagList | C18: =_xlfn.LET(_xlpm.x,VLOOKUP($B18,spell_header!$B$2:$G$373,2,FALSE),IF(_xlpm.x="","",_xlpm.x)) -> 所需目标单位标签列表 | D18: =IF(VLOOKUP($B18,spell_header!$B$2:$G$373,3,FALSE)="√","√","") -> √ | E18: =IF(VLOOKUP($B18,spell_header!$B$2:$G$373,4,FALSE)="√","√","") | F18: =_xlfn.LET(_xlpm.x,VLOOKUP($B18,spell_header!$B$2:$G$373,5,FALSE),IF(_xlpm.x="","",_xlpm.x)) | G18: 79
A19: 17 | B19: mSpell mExcludedUnitTags mObjectTagList | C19: =_xlfn.LET(_xlpm.x,VLOOKUP($B19,spell_header!$B$2:$G$373,2,FALSE),IF(_xlpm.x="","",_xlpm.x)) -> 无效目标单位标签列表 | D19: =IF(VLOOKUP($B19,spell_header!$B$2:$G$373,3,FALSE)="√","√","") -> √ | E19: =IF(VLOOKUP($B19,spell_header!$B$2:$G$373,4,FALSE)="√","√","") | F19: =_xlfn.LET(_xlpm.x,VLOOKUP($B19,spell_header!$B$2:$G$373,5,FALSE),IF(_xlpm.x="","",_xlpm.x)) | G19: 80
A20: 18 | B20: mSpell mPlatformSpellInfo mAvatarLevelRequired | C20: =_xlfn.LET(_xlpm.x,VLOOKUP($B20,spell_header!$B$2:$G$373,2,FALSE),IF(_xlpm.x="","",_xlpm.x)) -> 展现化身所需等级 | D20: =IF(VLOOKUP($B20,spell_header!$B$2:$G$373,3,FALSE)="√","√","") -> √ | E20: =IF(VLOOKUP($B20,spell_header!$B$2:$G$373,4,FALSE)="√","√","") -> √ | F20: =_xlfn.LET(_xlpm.x,VLOOKUP($B20,spell_header!$B$2:$G$373,5,FALSE),IF(_xlpm.x="","",_xlpm.x)) | G20: 83
A21: 19 | B21: mSpell mPlatformSpellInfo mSpellID | C21: =_xlfn.LET(_xlpm.x,VLOOKUP($B21,spell_header!$B$2:$G$373,2,FALSE),IF(_xlpm.x="","",_xlpm.x)) -> 指令序号 | D21: =IF(VLOOKUP($B21,spell_header!$B$2:$G$373,3,FALSE)="√","√","") -> √ | E21: =IF(VLOOKUP($B21,spell_header!$B$2:$G$373,4,FALSE)="√","√","") -> √ | F21: =_xlfn.LET(_xlpm.x,VLOOKUP($B21,spell_header!$B$2:$G$373,5,FALSE),IF(_xlpm.x="","",_xlpm.x)) | G21: 82
... A381: 379 | B381: BotData {591f8423} | C381: =_xlfn.LET(_xlpm.x,VLOOKUP($B381,spell_header!$B$2:$G$373,2,FALSE),IF(_xlpm.x="","",_xlpm.x)) | D381: =IF(VLOOKUP($B381,spell_header!$B$2:$G$373,3,FALSE)="√","√","") -> √ | E381: =IF(VLOOKUP($B381,spell_header!$B$2:$G$373,4,FALSE)="√","√","") -> √ | F381: =_xlfn.LET(_xlpm.x,VLOOKUP($B381,spell_header!$B$2:$G$373,5,FALSE),IF(_xlpm.x="","",_xlpm.x)) | G381: 379

Sheet item_header
A1: Index | B1: Key | C1: Value | D1: DirectlyImport? | E1: Flexible | F1: defaultValue | G1: OutputOrder
A2: 0 | B2: key | C2: 主键 | D2: √ | G2: 0
A3: 1 | B3: spellName | C3: 施法事件名称 | D3: √ | E3: √ | G3: 8
A4: 2 | B4: mDisplayName | C4: 显示名键 | D4: √ | E4: √ | G4: 2
A5: 3 | B5: mRequiredPurchaseIdentities | C5: 购买所需条件 | D5: √ | E5: √ | G5: 49
A6: 4 | B6: mRequiredChampion | C6: 适用英雄 | D6: √ | E6: √ | G6: 50
A7: 5 | B7: mRequiredSpellName | C7: 所需指令名 | D7: √ | E7: √ | G7: 52
A8: 6 | B8: mDisabledDescriptionOverride | C8: 禁用信息重载 | D8: √ | E8: √ | G8: 56
A9: 7 | B9: mDeathRecapName | C9: 死亡回放代码 | D9: √ | E9: √ | G9: 5
A10: 8 | B10: mRequiredLevel | C10: 所需英雄等级 | D10: √ | E10: √ | G10: 51
A11: 9 | B11: itemID | C11: 装备序号 | D11: √ | G11: 1
A12: 10 | B12: maxStack | C12: 最大持有数量 | D12: √ | E12: √ | G12: 26
A13: 11 | B13: mItemGroups | C13: 装备分组 | D13: √ | G13: 45
A14: 12 | B14: mItemAdviceAttributes | C14: 装备推荐属性 | D14: √ | E14: √ | G14: 46
A15: 13 | B15: itemVOGroup | C15: 装备音效分组 | D15: √ | E15: √ | G15: 48
A16: 14 | B16: price | C16: 合成费用 | D16: √ | E16: √ | G16: 27
A17: 15 | B17: mRequiredBuffCurrencyCost | C17: 其它费用 | D17: √ | E17: √ | G17: 30
A18: 16 | B18: mItemCalloutPlayer | C18: 购买时弹出提示 | D18: √ | E18: √ | F18: FALSE | G18: 57
A19: 17 | B19: mRequiredBuffCurrencyName | C19: 其它货币类型 | D19: √ | E19: √ | G19: 29
A20: 18 | B20: RestrictedBuffName | C20: 限定增益名称 | D20: √ | E20: √ | G20: 58
A21: 19 | B21: consumed | C21: 消耗品 | D21: √ | E21: √ | F21: FALSE | G21: 7
A22: 20 | B22: usableInStore | C22: 商店中可用 | D22: √ | E22: √ | F22: FALSE | G22: 12
A23: 21 | B23: consumeOnAcquire | C23: 购买时消耗 | D23: √ | E23: √ | F23: FALSE | G23: 13
A24: 22 | B24: clickable | C24: 可单击使用 | D24: √ | E24: √ | F24: FALSE | G24: 6
A25: 23 | B25: mHiddenFromOpponents | C25: 对手不可见 | D25: √ | E25: √ | F25: FALSE | G25: 14
A26: 24 | B26: mItemCalloutSpectator | C26: 观战购买时弹出提示 | D26: √ | E26: √ | F26: FALSE | G26: 15
A27: 25 | B27: ShowCooldownVfxToAllies | C27: 友军可见冷却时间 | D27: √ | E27: √ | F27: TRUE | G27: 16
A28: 26 | B28: ShowCooldownInPings | C28: 可标记冷却时间 | D28: √ | E28: √ | F28: TRUE | G28: 17
A29: 27 | B29: mCanBeSold | C29: 可以售出 | D29: √ | E29: √ | F29: FALSE | G29: 10
A30: 28 | B30: specialRecipe | C30: 特殊合成材料序号 | D30: √ | E30: √ | G30: 31
A31: 29 | B31: epicness | C31: 稀有度指数 | D31: √ | E31: √ | G31: 41
A32: 30 | B32: SecondaryEpicness | C32: 次要稀有度指数 | D32: √ | E32: √ | G32: 43
A33: 31 | B33: sidegradeItemLinks | C33: 同级替换路径 | D33: √ | E33: √ | G33: 34
A34: 32 | B34: mEffectAmount | C34: 因子取值 | D34: √ | E34: √ | G34: 88
A35: 33 | B35: recipeItemLinks | C35: 合成路径 | D35: √ | E35: √ | G35: 23
A36: 34 | B36: requiredItemLinks | C36: 所需装备路径 | D36: √ | E36: √ | G36: 53
A37: 35 | B37: mScripts | C37: 指令 | D37: √ | E37: √ | G37: 9
A38: 36 | B38: mItemModifiers | C38: 装备调整策略 | D38: √ | E38: √ | G38: 90
A39: 37 | B39: mDataValues | C39: 数值 | D39: √ | E39: √ | G39: 91
A40: 38 | B40: mFlatAttackRangeMod | C40: 固定攻击距离 | D40: √ | E40: √ | G40: 85
...

Sheet itemGroup_header
A1: Index | B1: Key | C1: Value | D1: DirectlyImport? | E1: Flexible | F1: defaultValue | G1: OutputOrder
A2: 0 | B2: key | C2: 主键 | D2: √ | G2: 0
A3: 1 | B3: mItemGroupID | C3: 装备分组名称 | D3: √ | G3: 1
A4: 2 | B4: mItemModifiers | C4: 装备修饰方案 | D4: √ | E4: √ | G4: 3
A5: 3 | B5: mInventorySlotMin | C5: 装备栏最小槽位号 | D5: √ | E5: √ | G5: 4
A6: 4 | B6: mInventorySlotMax | C6: 装备栏最大槽位号 | D6: √ | E6: √ | G6: 5
A7: 5 | B7: mMaxGroupOwnable | C7: 组内最多持有装备数量 | D7: √ | E7: √ | G7: 2
A8: 6 | B8: {dbc029fa} | D8: √ | E8: √ | F8: FALSE | G8: 7
A9: 7 | B9: mPurchaseCooldown | C9: 连点预防间隔（秒） | D9: √ | E9: √ | G9: 6

Sheet itemModifier_header
A1: Index | B1: Key | C1: Value | D1: DirectlyImport? | E1: Flexible | F1: defaultValue | G1: OutputOrder
A2: 0 | B2: key | C2: 主键 | D2: √ | G2: 0
A3: 1 | B3: mItemModifierID | C3: 装备修饰名称 | D3: √ | G3: 1
A4: 2 | B4: mModifiedIfBuildsFromItem | C4: 合成构件包含以下装备时修饰 | D4: √ | E4: √ | G4: 18
A5: 3 | B5: mModifiedItem | C5: 修饰装备 | D5: √ | E5: √ | G5: 2
A6: 4 | B6: mDeltaMaxStacks | C6: 最大持有数量变化值 | D6: √ | E6: √ | G6: 10
A7: 5 | B7: mModifiedGroup | C7: 修饰装备分组 | D7: √ | E7: √ | G7: 5
A8: 6 | B8: mMaximumModifierInstancesToBeActive | C8: 最大生效实例数量 | D8: √ | E8: √ | G8: 11
A9: 7 | B9: {06d9d838} | C9: 修饰前的基础构件 | D9: √ | E9: √ | G9: 21
A10: 8 | B10: {917537a9} | C10: 修饰后的基础构件 | D10: √ | E10: √ | G10: 24
A11: 9 | B11: mModifierIsInheritedByOwnedParentItems | C11: 大件继承构件修饰 | D11: √ | E11: √ | F11: FALSE | G11: 7
A12: 10 | B12: mIgnoreSpecificMaxGroupOwnable | C12: 不受其它最大持有数量限制影响 | D12: √ | E12: √ | F12: FALSE | G12: 8
A13: 11 | B13: mMaximumDeltasToStack | C13: 效果叠加次数最大变化量 | D13: √ | E13: √ | G13: 17
A14: 12 | B14: mShowAsModifiedInUI | C14: 显示为已修饰 | D14: √ | E14: √ | F14: FALSE | G14: 6
A15: 13 | B15: mDeltaGoldCostPercent | C15: 折扣 | D15: √ | E15: √ | G15: 16
A16: 14 | B16: mDeltaRequiredLevel | C16: 所需等级变化值 | D16: √ | E16: √ | G16: 12
A17: 15 | B17: mDeltaGoldCost | C17: 固定价格变化 | D17: √ | E17: √ | G17: 15
A18: 16 | B18: mDescriptionToReplace | C18: 替代简述键 | D18: √ | E18: √ | G18: 36
A19: 17 | B19: mDynamicTooltipToReplace | C19: 替代动态详细信息键 | D19: √ | E19: √ | G19: 39
A20: 18 | B20: mVisualPriority | C20: 计分板排列优先级 | D20: √ | E20: √ | G20: 14
A21: 19 | B21: inventoryIconToOverlay | C21: 装备栏覆盖图标路径 | D21: √ | E21: √ | G21: 48
A22: 20 | B22: mDescriptionToAppend | C22: 追加简述键 | D22: √ | E22: √ | G22: 42
A23: 21 | B23: mDynamicTooltipToAppend | C23: 追加动态详细信息键 | D23: √ | E23: √ | G23: 45
A24: 22 | B24: mDisplayNameToAppend | C24: 追加显示名键 | D24: √ | E24: √ | G24: 27
A25: 23 | B25: mDisplayNameToReplace | C25: 替代显示名键 | D25: √ | E25: √ | G25: 30
A26: 24 | B26: mDisplayNameToPrepend | C26: 前附显示名键 | D26: √ | E26: √ | G26: 33
A27: 25 | B27: mClickableToEnable | C27: 单击使用技能 | D27: √ | E27: √ | F27: FALSE | G27: 9
A28: 26 | B28: mSpellNameToReplace | C28: 取代技能名称 | D28: √ | E28: √ | G28: 13
A29: 27 | B29: {20b65c83} | C29: 升级边框方案名称 | D29: √ | E29: √ | G29: 49
A30: 28 | B30: mModifiedIfBuildsFromItem_mDisplayName_content_zh | C30: 修饰构件装备名称（中文） | E30: √ | G30: 19
A31: 29 | B31: mModifiedIfBuildsFromItem_mDisplayName_content_en | C31: 修饰构件装备名称（英文） | E31: √ | G31: 20
A32: 30 | B32: mModifiedItem_mDisplayName_content_zh | C32: 修饰装备名称（中文） | E32: √ | G32: 3
A33: 31 | B33: mModifiedItem_mDisplayName_content_en | C33: 修饰装备名称（英文） | E33: √ | G33: 4
A34: 32 | B34: {06d9d838}_mDisplayName_content_zh | C34: 修饰前的基础构件名称（中文） | E34: √ | G34: 22
A35: 33 | B35: {06d9d838}_mDisplayName_content_en | C35: 修饰前的基础构件名称（英文） | E35: √ | G35: 23
A36: 34 | B36: {917537a9}_mDisplayName_content_zh | C36: 修饰后的基础构件名称（中文） | E36: √ | G36: 25
A37: 35 | B37: {917537a9}_mDisplayName_content_en | C37: 修饰后的基础构件名称（英文） | E37: √ | G37: 26
A38: 36 | B38: mDescriptionToReplace_content_zh | C38: 替代简述（中文） | E38: √ | G38: 37
A39: 37 | B39: mDescriptionToReplace_content_en | C39: 替代简述（英文） | E39: √ | G39: 38
A40: 38 | B40: mDynamicTooltipToReplace_content_zh | C40: 替代动态详细信息（中文） | E40: √ | G40: 40
...

Sheet augment_header
A1: Index | B1: Key | C1: Value | D1: DirectlyImport? | E1: Flexible | F1: defaultValue | G1: OutputOrder
A2: 0 | B2: key | C2: 主键 | D2: √ | G2: 0
A3: 1 | B3: AugmentNameId | C3: 强化符文代码 | D3: √ | G3: 1
A4: 2 | B4: Enabled | C4: 可用性 | D4: √ | E4: √ | F4: TRUE | G4: 3
A5: 3 | B5: NameTra | C5: 名称键 | D5: √ | G5: 4
A6: 4 | B6: DescriptionTra | C6: 简介键 | D6: √ | G6: 21
A7: 5 | B7: AugmentTooltipTra | C7: 强化符文详细信息键 | D7: √ | G7: 26
A8: 6 | B8: RootSpell | C8: 根指令主键 | D8: √ | G8: 56
A9: 7 | B9: AdditionalSpells | C9: 其它指令主键列表 | D9: √ | G9: 58
A10: 8 | B10: mAugmentTags | C10: 强化符文标签 | D10: √ | E10: √ | G10: 15
A11: 9 | B11: mBuildTags | C11: 构建标签 | D11: √ | E11: √ | G11: 16
A12: 10 | B12: {3696d198} {c4182067} | C12: 强化符文详细信息描述部分键 | D12: √ | G12: 31
A13: 11 | B13: {3696d198} {231af825} | C13: 强化符文详细信息追踪部分键 | D13: √ | E13: √ | G13: 36
A14: 12 | B14: {791eb92e} {5753a320} {c98a82ca} | C14: 满级效果简介键 | D14: √ | G14: 41
A15: 13 | B15: {791eb92e} {5753a320} {05835d27} | C15: 满级效果详细信息键 | D15: √ | G15: 46
A16: 14 | B16: AugmentLargeIconPath | C16: 强化符文大图标路径 | D16: √ | G16: 64
A17: 15 | B17: AugmentSmallIconPath | C17: 强化符文小图标路径 | D17: √ | G17: 65
A18: 16 | B18: {815dad28} | C18: 次级稀有度 | D18: √ | E18: √ | G18: 9
A19: 17 | B19: AugmentDisplayTags | C19: 强化符文显示标签 | D19: √ | G19: 11
A20: 18 | B20: rarity | C20: 稀有度 | D20: √ | E20: √ | G20: 7
A21: 19 | B21: {ed593c9c} | C21: 不占用栏位 | D21: √ | E21: √ | F21: FALSE | G21: 17
A22: 20 | B22: AugmentPlatformId | C22: 强化符文序号 | D22: √ | F22: -1 | G22: 2
A23: 21 | B23: QuestData Quest | C23: 任务线主键 | D23: √ | E23: √ | G23: 60
A24: 22 | B24: {e3a02eac} | C24: 技能重载 | D24: √ | E24: √ | F24: FALSE | G24: 18
A25: 23 | B25: ResourceResolver | C25: 资源解析器主键 | D25: √ | E25: √ | G25: 62
A26: 24 | B26: NameTra_content_zh | C26: 名称（中文） | G26: 5
A27: 25 | B27: NameTra_content_en | C27: 名称（英文） | G27: 6
A28: 26 | B28: DescriptionTra_content_zh | C28: 简介（中文） | G28: 22
A29: 27 | B29: DescriptionTra_content_zh_burn | C29: 简介（中文/数值转换） | G29: 23
A30: 28 | B30: DescriptionTra_content_en | C30: 简介（英文） | G30: 24
A31: 29 | B31: DescriptionTra_content_en_burn | C31: 简介（英文/数值转换） | G31: 25
A32: 30 | B32: AugmentTooltipTra_content_zh | C32: 强化符文详细信息（中文） | G32: 27
A33: 31 | B33: AugmentTooltipTra_content_zh_burn | C33: 强化符文详细信息（中文/数值转换） | G33: 28
A34: 32 | B34: AugmentTooltipTra_content_en | C34: 强化符文详细信息（英文） | G34: 29
A35: 33 | B35: AugmentTooltipTra_content_en_burn | C35: 强化符文详细信息（英文/数值转换） | G35: 30
A36: 34 | B36: {3696d198} {c4182067}_content_zh | C36: 强化符文详细信息描述部分（中文） | G36: 32
A37: 35 | B37: {3696d198} {c4182067}_content_zh_burn | C37: 强化符文详细信息描述部分（中文/数值转换） | G37: 33
... A52: 50 | B52: AugmentDisplayTags_content | C52: 强化符文显示标签内容 | G52: 12
A53: 51 | B53: rarityValue | C53: 位阶 | E53: √ | G53: 8
A54: 52 | B54: RootSpellObject | C54: 根指令对象 | D54: √ | G54: 57
...

Sheet CherryAugment_header
A1: Index | B1: Key | C1: Value | D1: DirectlyImport? | E1: Flexible | F1: defaultValue | G1: OutputOrder
A2: 0 | B2: key | C2: =_xlfn.LET(_xlpm.x,VLOOKUP($B2,augment_header!$B$2:$G$72,2,FALSE),IF(_xlpm.x="","",_xlpm.x)) -> 主键 | D2: =IF(VLOOKUP($B2,augment_header!$B$2:$G$72,3,FALSE)="√","√","") -> √ | E2: =IF(VLOOKUP($B2,augment_header!$B$2:$G$72,4,FALSE)="√","√","") | F2: =_xlfn.LET(_xlpm.x,VLOOKUP($B2,augment_header!$B$2:$G$72,5,FALSE),IF(_xlpm.x="","",_xlpm.x)) | G2: 0
A3: 1 | B3: AugmentNameId | C3: =_xlfn.LET(_xlpm.x,VLOOKUP($B3,augment_header!$B$2:$G$72,2,FALSE),IF(_xlpm.x="","",_xlpm.x)) -> 强化符文代码 | D3: =IF(VLOOKUP($B3,augment_header!$B$2:$G$72,3,FALSE)="√","√","") -> √ | E3: =IF(VLOOKUP($B3,augment_header!$B$2:$G$72,4,FALSE)="√","√","") | F3: =_xlfn.LET(_xlpm.x,VLOOKUP($B3,augment_header!$B$2:$G$72,5,FALSE),IF(_xlpm.x="","",_xlpm.x)) | G3: 1
A4: 2 | B4: Enabled | C4: =_xlfn.LET(_xlpm.x,VLOOKUP($B4,augment_header!$B$2:$G$72,2,FALSE),IF(_xlpm.x="","",_xlpm.x)) -> 可用性 | D4: =IF(VLOOKUP($B4,augment_header!$B$2:$G$72,3,FALSE)="√","√","") -> √ | E4: =IF(VLOOKUP($B4,augment_header!$B$2:$G$72,4,FALSE)="√","√","") -> √ | F4: =_xlfn.LET(_xlpm.x,VLOOKUP($B4,augment_header!$B$2:$G$72,5,FALSE),IF(_xlpm.x="","",_xlpm.x)) -> TRUE | G4: 3
A5: 3 | B5: NameTra | C5: =_xlfn.LET(_xlpm.x,VLOOKUP($B5,augment_header!$B$2:$G$72,2,FALSE),IF(_xlpm.x="","",_xlpm.x)) -> 名称键 | D5: =IF(VLOOKUP($B5,augment_header!$B$2:$G$72,3,FALSE)="√","√","") -> √ | E5: =IF(VLOOKUP($B5,augment_header!$B$2:$G$72,4,FALSE)="√","√","") | F5: =_xlfn.LET(_xlpm.x,VLOOKUP($B5,augment_header!$B$2:$G$72,5,FALSE),IF(_xlpm.x="","",_xlpm.x)) | G5: 4
A6: 4 | B6: DescriptionTra | C6: =_xlfn.LET(_xlpm.x,VLOOKUP($B6,augment_header!$B$2:$G$72,2,FALSE),IF(_xlpm.x="","",_xlpm.x)) -> 简介键 | D6: =IF(VLOOKUP($B6,augment_header!$B$2:$G$72,3,FALSE)="√","√","") -> √ | E6: =IF(VLOOKUP($B6,augment_header!$B$2:$G$72,4,FALSE)="√","√","") | F6: =_xlfn.LET(_xlpm.x,VLOOKUP($B6,augment_header!$B$2:$G$72,5,FALSE),IF(_xlpm.x="","",_xlpm.x)) | G6: 16
A7: 5 | B7: AugmentTooltipTra | C7: =_xlfn.LET(_xlpm.x,VLOOKUP($B7,augment_header!$B$2:$G$72,2,FALSE),IF(_xlpm.x="","",_xlpm.x)) -> 强化符文详细信息键 | D7: =IF(VLOOKUP($B7,augment_header!$B$2:$G$72,3,FALSE)="√","√","") -> √ | E7: =IF(VLOOKUP($B7,augment_header!$B$2:$G$72,4,FALSE)="√","√","") | F7: =_xlfn.LET(_xlpm.x,VLOOKUP($B7,augment_header!$B$2:$G$72,5,FALSE),IF(_xlpm.x="","",_xlpm.x)) | G7: 21
A8: 6 | B8: RootSpell | C8: =_xlfn.LET(_xlpm.x,VLOOKUP($B8,augment_header!$B$2:$G$72,2,FALSE),IF(_xlpm.x="","",_xlpm.x)) -> 根指令主键 | D8: =IF(VLOOKUP($B8,augment_header!$B$2:$G$72,3,FALSE)="√","√","") -> √ | E8: =IF(VLOOKUP($B8,augment_header!$B$2:$G$72,4,FALSE)="√","√","") | F8: =_xlfn.LET(_xlpm.x,VLOOKUP($B8,augment_header!$B$2:$G$72,5,FALSE),IF(_xlpm.x="","",_xlpm.x)) | G8: 46
A9: 7 | B9: AdditionalSpells | C9: =_xlfn.LET(_xlpm.x,VLOOKUP($B9,augment_header!$B$2:$G$72,2,FALSE),IF(_xlpm.x="","",_xlpm.x)) -> 其它指令主键列表 | D9: =IF(VLOOKUP($B9,augment_header!$B$2:$G$72,3,FALSE)="√","√","") -> √ | E9: =IF(VLOOKUP($B9,augment_header!$B$2:$G$72,4,FALSE)="√","√","") | F9: =_xlfn.LET(_xlpm.x,VLOOKUP($B9,augment_header!$B$2:$G$72,5,FALSE),IF(_xlpm.x="","",_xlpm.x))
A10: 8 | B10: mAugmentTags | C10: =_xlfn.LET(_xlpm.x,VLOOKUP($B10,augment_header!$B$2:$G$72,2,FALSE),IF(_xlpm.x="","",_xlpm.x)) -> 强化符文标签 | D10: =IF(VLOOKUP($B10,augment_header!$B$2:$G$72,3,FALSE)="√","√","") -> √ | E10: =IF(VLOOKUP($B10,augment_header!$B$2:$G$72,4,FALSE)="√","√","") -> √ | F10: =_xlfn.LET(_xlpm.x,VLOOKUP($B10,augment_header!$B$2:$G$72,5,FALSE),IF(_xlpm.x="","",_xlpm.x)) | G10: 13
A11: 9 | B11: mBuildTags | C11: =_xlfn.LET(_xlpm.x,VLOOKUP($B11,augment_header!$B$2:$G$72,2,FALSE),IF(_xlpm.x="","",_xlpm.x)) -> 构建标签 | D11: =IF(VLOOKUP($B11,augment_header!$B$2:$G$72,3,FALSE)="√","√","") -> √ | E11: =IF(VLOOKUP($B11,augment_header!$B$2:$G$72,4,FALSE)="√","√","") -> √ | F11: =_xlfn.LET(_xlpm.x,VLOOKUP($B11,augment_header!$B$2:$G$72,5,FALSE),IF(_xlpm.x="","",_xlpm.x)) | G11: 14
A12: 10 | B12: {3696d198} {c4182067} | C12: =_xlfn.LET(_xlpm.x,VLOOKUP($B12,augment_header!$B$2:$G$72,2,FALSE),IF(_xlpm.x="","",_xlpm.x)) -> 强化符文详细信息描述部分键 | D12: =IF(VLOOKUP($B12,augment_header!$B$2:$G$72,3,FALSE)="√","√","") -> √ | E12: =IF(VLOOKUP($B12,augment_header!$B$2:$G$72,4,FALSE)="√","√","") | F12: =_xlfn.LET(_xlpm.x,VLOOKUP($B12,augment_header!$B$2:$G$72,5,FALSE),IF(_xlpm.x="","",_xlpm.x)) | G12: 26
A13: 11 | B13: {3696d198} {231af825} | C13: =_xlfn.LET(_xlpm.x,VLOOKUP($B13,augment_header!$B$2:$G$72,2,FALSE),IF(_xlpm.x="","",_xlpm.x)) -> 强化符文详细信息追踪部分键 | D13: =IF(VLOOKUP($B13,augment_header!$B$2:$G$72,3,FALSE)="√","√","") -> √ | E13: =IF(VLOOKUP($B13,augment_header!$B$2:$G$72,4,FALSE)="√","√","") -> √ | F13: =_xlfn.LET(_xlpm.x,VLOOKUP($B13,augment_header!$B$2:$G$72,5,FALSE),IF(_xlpm.x="","",_xlpm.x)) | G13: 31
A14: 12 | B14: {791eb92e} {5753a320} {c98a82ca} | C14: =_xlfn.LET(_xlpm.x,VLOOKUP($B14,augment_header!$B$2:$G$72,2,FALSE),IF(_xlpm.x="","",_xlpm.x)) -> 满级效果简介键 | D14: =IF(VLOOKUP($B14,augment_header!$B$2:$G$72,3,FALSE)="√","√","") -> √ | E14: =IF(VLOOKUP($B14,augment_header!$B$2:$G$72,4,FALSE)="√","√","") | F14: =_xlfn.LET(_xlpm.x,VLOOKUP($B14,augment_header!$B$2:$G$72,5,FALSE),IF(_xlpm.x="","",_xlpm.x)) | G14: 36
A15: 13 | B15: {791eb92e} {5753a320} {05835d27} | C15: =_xlfn.LET(_xlpm.x,VLOOKUP($B15,augment_header!$B$2:$G$72,2,FALSE),IF(_xlpm.x="","",_xlpm.x)) -> 满级效果详细信息键 | D15: =IF(VLOOKUP($B15,augment_header!$B$2:$G$72,3,FALSE)="√","√","") -> √ | E15: =IF(VLOOKUP($B15,augment_header!$B$2:$G$72,4,FALSE)="√","√","") | F15: =_xlfn.LET(_xlpm.x,VLOOKUP($B15,augment_header!$B$2:$G$72,5,FALSE),IF(_xlpm.x="","",_xlpm.x)) | G15: 41
A16: 14 | B16: AugmentLargeIconPath | C16: =_xlfn.LET(_xlpm.x,VLOOKUP($B16,augment_header!$B$2:$G$72,2,FALSE),IF(_xlpm.x="","",_xlpm.x)) -> 强化符文大图标路径 | D16: =IF(VLOOKUP($B16,augment_header!$B$2:$G$72,3,FALSE)="√","√","") -> √ | E16: =IF(VLOOKUP($B16,augment_header!$B$2:$G$72,4,FALSE)="√","√","") | F16: =_xlfn.LET(_xlpm.x,VLOOKUP($B16,augment_header!$B$2:$G$72,5,FALSE),IF(_xlpm.x="","",_xlpm.x)) | G16: 48
A17: 15 | B17: AugmentSmallIconPath | C17: =_xlfn.LET(_xlpm.x,VLOOKUP($B17,augment_header!$B$2:$G$72,2,FALSE),IF(_xlpm.x="","",_xlpm.x)) -> 强化符文小图标路径 | D17: =IF(VLOOKUP($B17,augment_header!$B$2:$G$72,3,FALSE)="√","√","") -> √ | E17: =IF(VLOOKUP($B17,augment_header!$B$2:$G$72,4,FALSE)="√","√","") | F17: =_xlfn.LET(_xlpm.x,VLOOKUP($B17,augment_header!$B$2:$G$72,5,FALSE),IF(_xlpm.x="","",_xlpm.x)) | G17: 49
A18: 16 | B18: {815dad28} | C18: =_xlfn.LET(_xlpm.x,VLOOKUP($B18,augment_header!$B$2:$G$72,2,FALSE),IF(_xlpm.x="","",_xlpm.x)) -> 次级稀有度 | D18: =IF(VLOOKUP($B18,augment_header!$B$2:$G$72,3,FALSE)="√","√","") -> √ | E18: =IF(VLOOKUP($B18,augment_header!$B$2:$G$72,4,FALSE)="√","√","") -> √ | F18: =_xlfn.LET(_xlpm.x,VLOOKUP($B18,augment_header!$B$2:$G$72,5,FALSE),IF(_xlpm.x="","",_xlpm.x)) | G18: 9
A19: 17 | B19: AugmentDisplayTags | C19: =_xlfn.LET(_xlpm.x,VLOOKUP($B19,augment_header!$B$2:$G$72,2,FALSE),IF(_xlpm.x="","",_xlpm.x)) -> 强化符文显示标签 | D19: =IF(VLOOKUP($B19,augment_header!$B$2:$G$72,3,FALSE)="√","√","") -> √ | E19: =IF(VLOOKUP($B19,augment_header!$B$2:$G$72,4,FALSE)="√","√","") | F19: =_xlfn.LET(_xlpm.x,VLOOKUP($B19,augment_header!$B$2:$G$72,5,FALSE),IF(_xlpm.x="","",_xlpm.x)) | G19: 11
A20: 18 | B20: rarity | C20: =_xlfn.LET(_xlpm.x,VLOOKUP($B20,augment_header!$B$2:$G$72,2,FALSE),IF(_xlpm.x="","",_xlpm.x)) -> 稀有度 | D20: =IF(VLOOKUP($B20,augment_header!$B$2:$G$72,3,FALSE)="√","√","") -> √ | E20: =IF(VLOOKUP($B20,augment_header!$B$2:$G$72,4,FALSE)="√","√","") -> √ | F20: =_xlfn.LET(_xlpm.x,VLOOKUP($B20,augment_header!$B$2:$G$72,5,FALSE),IF(_xlpm.x="","",_xlpm.x)) | G20: 7
A21: 19 | B21: {ed593c9c} | C21: =_xlfn.LET(_xlpm.x,VLOOKUP($B21,augment_header!$B$2:$G$72,2,FALSE),IF(_xlpm.x="","",_xlpm.x)) -> 不占用栏位 | D21: =IF(VLOOKUP($B21,augment_header!$B$2:$G$72,3,FALSE)="√","√","") -> √ | E21: =IF(VLOOKUP($B21,augment_header!$B$2:$G$72,4,FALSE)="√","√","") -> √ | F21: =_xlfn.LET(_xlpm.x,VLOOKUP($B21,augment_header!$B$2:$G$72,5,FALSE),IF(_xlpm.x="","",_xlpm.x)) -> FALSE | G21: 15
A22: 20 | B22: AugmentPlatformId | C22: =_xlfn.LET(_xlpm.x,VLOOKUP($B22,augment_header!$B$2:$G$72,2,FALSE),IF(_xlpm.x="","",_xlpm.x)) -> 强化符文序号 | D22: =IF(VLOOKUP($B22,augment_header!$B$2:$G$72,3,FALSE)="√","√","") -> √ | E22: =IF(VLOOKUP($B22,augment_header!$B$2:$G$72,4,FALSE)="√","√","") | F22: =_xlfn.LET(_xlpm.x,VLOOKUP($B22,augment_header!$B$2:$G$72,5,FALSE),IF(_xlpm.x="","",_xlpm.x)) -> -1 | G22: 2
A23: 21 | B23: QuestData Quest | C23: =_xlfn.LET(_xlpm.x,VLOOKUP($B23,augment_header!$B$2:$G$72,2,FALSE),IF(_xlpm.x="","",_xlpm.x)) -> 任务线主键 | D23: =IF(VLOOKUP($B23,augment_header!$B$2:$G$72,3,FALSE)="√","√","") -> √ | E23: =IF(VLOOKUP($B23,augment_header!$B$2:$G$72,4,FALSE)="√","√","") -> √ | F23: =_xlfn.LET(_xlpm.x,VLOOKUP($B23,augment_header!$B$2:$G$72,5,FALSE),IF(_xlpm.x="","",_xlpm.x))
A24: 22 | B24: {e3a02eac} | C24: =_xlfn.LET(_xlpm.x,VLOOKUP($B24,augment_header!$B$2:$G$72,2,FALSE),IF(_xlpm.x="","",_xlpm.x)) -> 技能重载 | D24: =IF(VLOOKUP($B24,augment_header!$B$2:$G$72,3,FALSE)="√","√","") -> √ | E24: =IF(VLOOKUP($B24,augment_header!$B$2:$G$72,4,FALSE)="√","√","") -> √ | F24: =_xlfn.LET(_xlpm.x,VLOOKUP($B24,augment_header!$B$2:$G$72,5,FALSE),IF(_xlpm.x="","",_xlpm.x)) -> FALSE
A25: 23 | B25: ResourceResolver | C25: =_xlfn.LET(_xlpm.x,VLOOKUP($B25,augment_header!$B$2:$G$72,2,FALSE),IF(_xlpm.x="","",_xlpm.x)) -> 资源解析器主键 | D25: =IF(VLOOKUP($B25,augment_header!$B$2:$G$72,3,FALSE)="√","√","") -> √ | E25: =IF(VLOOKUP($B25,augment_header!$B$2:$G$72,4,FALSE)="√","√","") -> √ | F25: =_xlfn.LET(_xlpm.x,VLOOKUP($B25,augment_header!$B$2:$G$72,5,FALSE),IF(_xlpm.x="","",_xlpm.x))
A26: 24 | B26: NameTra_content_zh | C26: =_xlfn.LET(_xlpm.x,VLOOKUP($B26,augment_header!$B$2:$G$72,2,FALSE),IF(_xlpm.x="","",_xlpm.x)) -> 名称（中文） | D26: =IF(VLOOKUP($B26,augment_header!$B$2:$G$72,3,FALSE)="√","√","") | E26: =IF(VLOOKUP($B26,augment_header!$B$2:$G$72,4,FALSE)="√","√","") | F26: =_xlfn.LET(_xlpm.x,VLOOKUP($B26,augment_header!$B$2:$G$72,5,FALSE),IF(_xlpm.x="","",_xlpm.x)) | G26: 5
A27: 25 | B27: NameTra_content_en | C27: =_xlfn.LET(_xlpm.x,VLOOKUP($B27,augment_header!$B$2:$G$72,2,FALSE),IF(_xlpm.x="","",_xlpm.x)) -> 名称（英文） | D27: =IF(VLOOKUP($B27,augment_header!$B$2:$G$72,3,FALSE)="√","√","") | E27: =IF(VLOOKUP($B27,augment_header!$B$2:$G$72,4,FALSE)="√","√","") | F27: =_xlfn.LET(_xlpm.x,VLOOKUP($B27,augment_header!$B$2:$G$72,5,FALSE),IF(_xlpm.x="","",_xlpm.x)) | G27: 6
A28: 26 | B28: DescriptionTra_content_zh | C28: =_xlfn.LET(_xlpm.x,VLOOKUP($B28,augment_header!$B$2:$G$72,2,FALSE),IF(_xlpm.x="","",_xlpm.x)) -> 简介（中文） | D28: =IF(VLOOKUP($B28,augment_header!$B$2:$G$72,3,FALSE)="√","√","") | E28: =IF(VLOOKUP($B28,augment_header!$B$2:$G$72,4,FALSE)="√","√","") | F28: =_xlfn.LET(_xlpm.x,VLOOKUP($B28,augment_header!$B$2:$G$72,5,FALSE),IF(_xlpm.x="","",_xlpm.x)) | G28: 17
A29: 27 | B29: DescriptionTra_content_zh_burn | C29: =_xlfn.LET(_xlpm.x,VLOOKUP($B29,augment_header!$B$2:$G$72,2,FALSE),IF(_xlpm.x="","",_xlpm.x)) -> 简介（中文/数值转换） | D29: =IF(VLOOKUP($B29,augment_header!$B$2:$G$72,3,FALSE)="√","√","") | E29: =IF(VLOOKUP($B29,augment_header!$B$2:$G$72,4,FALSE)="√","√","") | F29: =_xlfn.LET(_xlpm.x,VLOOKUP($B29,augment_header!$B$2:$G$72,5,FALSE),IF(_xlpm.x="","",_xlpm.x)) | G29: 18
A30: 28 | B30: DescriptionTra_content_en | C30: =_xlfn.LET(_xlpm.x,VLOOKUP($B30,augment_header!$B$2:$G$72,2,FALSE),IF(_xlpm.x="","",_xlpm.x)) -> 简介（英文） | D30: =IF(VLOOKUP($B30,augment_header!$B$2:$G$72,3,FALSE)="√","√","") | E30: =IF(VLOOKUP($B30,augment_header!$B$2:$G$72,4,FALSE)="√","√","") | F30: =_xlfn.LET(_xlpm.x,VLOOKUP($B30,augment_header!$B$2:$G$72,5,FALSE),IF(_xlpm.x="","",_xlpm.x)) | G30: 19
A31: 29 | B31: DescriptionTra_content_en_burn | C31: =_xlfn.LET(_xlpm.x,VLOOKUP($B31,augment_header!$B$2:$G$72,2,FALSE),IF(_xlpm.x="","",_xlpm.x)) -> 简介（英文/数值转换） | D31: =IF(VLOOKUP($B31,augment_header!$B$2:$G$72,3,FALSE)="√","√","") | E31: =IF(VLOOKUP($B31,augment_header!$B$2:$G$72,4,FALSE)="√","√","") | F31: =_xlfn.LET(_xlpm.x,VLOOKUP($B31,augment_header!$B$2:$G$72,5,FALSE),IF(_xlpm.x="","",_xlpm.x)) | G31: 20
A32: 30 | B32: AugmentTooltipTra_content_zh | C32: =_xlfn.LET(_xlpm.x,VLOOKUP($B32,augment_header!$B$2:$G$72,2,FALSE),IF(_xlpm.x="","",_xlpm.x)) -> 强化符文详细信息（中文） | D32: =IF(VLOOKUP($B32,augment_header!$B$2:$G$72,3,FALSE)="√","√","") | E32: =IF(VLOOKUP($B32,augment_header!$B$2:$G$72,4,FALSE)="√","√","") | F32: =_xlfn.LET(_xlpm.x,VLOOKUP($B32,augment_header!$B$2:$G$72,5,FALSE),IF(_xlpm.x="","",_xlpm.x)) | G32: 22
A33: 31 | B33: AugmentTooltipTra_content_zh_burn | C33: =_xlfn.LET(_xlpm.x,VLOOKUP($B33,augment_header!$B$2:$G$72,2,FALSE),IF(_xlpm.x="","",_xlpm.x)) -> 强化符文详细信息（中文/数值转换） | D33: =IF(VLOOKUP($B33,augment_header!$B$2:$G$72,3,FALSE)="√","√","") | E33: =IF(VLOOKUP($B33,augment_header!$B$2:$G$72,4,FALSE)="√","√","") | F33: =_xlfn.LET(_xlpm.x,VLOOKUP($B33,augment_header!$B$2:$G$72,5,FALSE),IF(_xlpm.x="","",_xlpm.x)) | G33: 23
A34: 32 | B34: AugmentTooltipTra_content_en | C34: =_xlfn.LET(_xlpm.x,VLOOKUP($B34,augment_header!$B$2:$G$72,2,FALSE),IF(_xlpm.x="","",_xlpm.x)) -> 强化符文详细信息（英文） | D34: =IF(VLOOKUP($B34,augment_header!$B$2:$G$72,3,FALSE)="√","√","") | E34: =IF(VLOOKUP($B34,augment_header!$B$2:$G$72,4,FALSE)="√","√","") | F34: =_xlfn.LET(_xlpm.x,VLOOKUP($B34,augment_header!$B$2:$G$72,5,FALSE),IF(_xlpm.x="","",_xlpm.x)) | G34: 24
A35: 33 | B35: AugmentTooltipTra_content_en_burn | C35: =_xlfn.LET(_xlpm.x,VLOOKUP($B35,augment_header!$B$2:$G$72,2,FALSE),IF(_xlpm.x="","",_xlpm.x)) -> 强化符文详细信息（英文/数值转换） | D35: =IF(VLOOKUP($B35,augment_header!$B$2:$G$72,3,FALSE)="√","√","") | E35: =IF(VLOOKUP($B35,augment_header!$B$2:$G$72,4,FALSE)="√","√","") | F35: =_xlfn.LET(_xlpm.x,VLOOKUP($B35,augment_header!$B$2:$G$72,5,FALSE),IF(_xlpm.x="","",_xlpm.x)) | G35: 25
A36: 34 | B36: {3696d198} {c4182067}_content_zh | C36: =_xlfn.LET(_xlpm.x,VLOOKUP($B36,augment_header!$B$2:$G$72,2,FALSE),IF(_xlpm.x="","",_xlpm.x)) -> 强化符文详细信息描述部分（中文） | D36: =IF(VLOOKUP($B36,augment_header!$B$2:$G$72,3,FALSE)="√","√","") | E36: =IF(VLOOKUP($B36,augment_header!$B$2:$G$72,4,FALSE)="√","√","") | F36: =_xlfn.LET(_xlpm.x,VLOOKUP($B36,augment_header!$B$2:$G$72,5,FALSE),IF(_xlpm.x="","",_xlpm.x)) | G36: 27
A37: 35 | B37: {3696d198} {c4182067}_content_zh_burn | C37: =_xlfn.LET(_xlpm.x,VLOOKUP($B37,augment_header!$B$2:$G$72,2,FALSE),IF(_xlpm.x="","",_xlpm.x)) -> 强化符文详细信息描述部分（中文/数值转换） | D37: =IF(VLOOKUP($B37,augment_header!$B$2:$G$72,3,FALSE)="√","√","") | E37: =IF(VLOOKUP($B37,augment_header!$B$2:$G$72,4,FALSE)="√","√","") | F37: =_xlfn.LET(_xlpm.x,VLOOKUP($B37,augment_header!$B$2:$G$72,5,FALSE),IF(_xlpm.x="","",_xlpm.x)) | G37: 28
... A54: 52 | B54: RootSpellObject | C54: =_xlfn.LET(_xlpm.x,VLOOKUP($B54,augment_header!$B$2:$G$72,2,FALSE),IF(_xlpm.x="","",_xlpm.x)) -> 根指令对象 | D54: =IF(VLOOKUP($B54,augment_header!$B$2:$G$72,3,FALSE)="√","√","") -> √ | E54: =IF(VLOOKUP($B54,augment_header!$B$2:$G$72,4,FALSE)="√","√","") | F54: =_xlfn.LET(_xlpm.x,VLOOKUP($B54,augment_header!$B$2:$G$72,5,FALSE),IF(_xlpm.x="","",_xlpm.x)) | G54: 47
A55: 53 | B55: AdditionalSpells_Object | C55: =_xlfn.LET(_xlpm.x,VLOOKUP($B55,augment_header!$B$2:$G$72,2,FALSE),IF(_xlpm.x="","",_xlpm.x)) -> 其它指令对象 | D55: =IF(VLOOKUP($B55,augment_header!$B$2:$G$72,3,FALSE)="√","√","") -> √ | E55: =IF(VLOOKUP($B55,augment_header!$B$2:$G$72,4,FALSE)="√","√","") | F55: =_xlfn.LET(_xlpm.x,VLOOKUP($B55,augment_header!$B$2:$G$72,5,FALSE),IF(_xlpm.x="","",_xlpm.x))
A56: 54 | B56: RootSpell mSpell DataValues MaxLevel | C56: =_xlfn.LET(_xlpm.x,VLOOKUP($B56,augment_header!$B$2:$G$72,2,FALSE),IF(_xlpm.x="","",_xlpm.x)) -> 最大等级 | D56: =IF(VLOOKUP($B56,augment_header!$B$2:$G$72,3,FALSE)="√","√","") -> √ | E56: =IF(VLOOKUP($B56,augment_header!$B$2:$G$72,4,FALSE)="√","√","") | F56: =_xlfn.LET(_xlpm.x,VLOOKUP($B56,augment_header!$B$2:$G$72,5,FALSE),IF(_xlpm.x="","",_xlpm.x)) | G56: 10
...

Sheet SwarmAugment_header
A1: Index | B1: Key | C1: Value | D1: DirectlyImport? | E1: Flexible | F1: defaultValue | G1: OutputOrder
A2: 0 | B2: key | C2: =_xlfn.LET(_xlpm.x,VLOOKUP($B2,augment_header!$B$2:$G$72,2,FALSE),IF(_xlpm.x="","",_xlpm.x)) -> 主键 | D2: =IF(VLOOKUP($B2,augment_header!$B$2:$G$72,3,FALSE)="√","√","") -> √ | E2: =IF(VLOOKUP($B2,augment_header!$B$2:$G$72,4,FALSE)="√","√","") | F2: =_xlfn.LET(_xlpm.x,VLOOKUP($B2,augment_header!$B$2:$G$72,5,FALSE),IF(_xlpm.x="","",_xlpm.x)) | G2: 0
A3: 1 | B3: AugmentNameId | C3: =_xlfn.LET(_xlpm.x,VLOOKUP($B3,augment_header!$B$2:$G$72,2,FALSE),IF(_xlpm.x="","",_xlpm.x)) -> 强化符文代码 | D3: =IF(VLOOKUP($B3,augment_header!$B$2:$G$72,3,FALSE)="√","√","") -> √ | E3: =IF(VLOOKUP($B3,augment_header!$B$2:$G$72,4,FALSE)="√","√","") | F3: =_xlfn.LET(_xlpm.x,VLOOKUP($B3,augment_header!$B$2:$G$72,5,FALSE),IF(_xlpm.x="","",_xlpm.x)) | G3: 1
A4: 2 | B4: Enabled | C4: =_xlfn.LET(_xlpm.x,VLOOKUP($B4,augment_header!$B$2:$G$72,2,FALSE),IF(_xlpm.x="","",_xlpm.x)) -> 可用性 | D4: =IF(VLOOKUP($B4,augment_header!$B$2:$G$72,3,FALSE)="√","√","") -> √ | E4: =IF(VLOOKUP($B4,augment_header!$B$2:$G$72,4,FALSE)="√","√","") -> √ | F4: =_xlfn.LET(_xlpm.x,VLOOKUP($B4,augment_header!$B$2:$G$72,5,FALSE),IF(_xlpm.x="","",_xlpm.x)) -> TRUE
A5: 3 | B5: NameTra | C5: =_xlfn.LET(_xlpm.x,VLOOKUP($B5,augment_header!$B$2:$G$72,2,FALSE),IF(_xlpm.x="","",_xlpm.x)) -> 名称键 | D5: =IF(VLOOKUP($B5,augment_header!$B$2:$G$72,3,FALSE)="√","√","") -> √ | E5: =IF(VLOOKUP($B5,augment_header!$B$2:$G$72,4,FALSE)="√","√","") | F5: =_xlfn.LET(_xlpm.x,VLOOKUP($B5,augment_header!$B$2:$G$72,5,FALSE),IF(_xlpm.x="","",_xlpm.x)) | G5: 3
A6: 4 | B6: DescriptionTra | C6: =_xlfn.LET(_xlpm.x,VLOOKUP($B6,augment_header!$B$2:$G$72,2,FALSE),IF(_xlpm.x="","",_xlpm.x)) -> 简介键 | D6: =IF(VLOOKUP($B6,augment_header!$B$2:$G$72,3,FALSE)="√","√","") -> √ | E6: =IF(VLOOKUP($B6,augment_header!$B$2:$G$72,4,FALSE)="√","√","") | F6: =_xlfn.LET(_xlpm.x,VLOOKUP($B6,augment_header!$B$2:$G$72,5,FALSE),IF(_xlpm.x="","",_xlpm.x)) | G6: 9
A7: 5 | B7: AugmentTooltipTra | C7: =_xlfn.LET(_xlpm.x,VLOOKUP($B7,augment_header!$B$2:$G$72,2,FALSE),IF(_xlpm.x="","",_xlpm.x)) -> 强化符文详细信息键 | D7: =IF(VLOOKUP($B7,augment_header!$B$2:$G$72,3,FALSE)="√","√","") -> √ | E7: =IF(VLOOKUP($B7,augment_header!$B$2:$G$72,4,FALSE)="√","√","") | F7: =_xlfn.LET(_xlpm.x,VLOOKUP($B7,augment_header!$B$2:$G$72,5,FALSE),IF(_xlpm.x="","",_xlpm.x)) | G7: 14
A8: 6 | B8: RootSpell | C8: =_xlfn.LET(_xlpm.x,VLOOKUP($B8,augment_header!$B$2:$G$72,2,FALSE),IF(_xlpm.x="","",_xlpm.x)) -> 根指令主键 | D8: =IF(VLOOKUP($B8,augment_header!$B$2:$G$72,3,FALSE)="√","√","") -> √ | E8: =IF(VLOOKUP($B8,augment_header!$B$2:$G$72,4,FALSE)="√","√","") | F8: =_xlfn.LET(_xlpm.x,VLOOKUP($B8,augment_header!$B$2:$G$72,5,FALSE),IF(_xlpm.x="","",_xlpm.x)) | G8: 19
A9: 7 | B9: AdditionalSpells | C9: =_xlfn.LET(_xlpm.x,VLOOKUP($B9,augment_header!$B$2:$G$72,2,FALSE),IF(_xlpm.x="","",_xlpm.x)) -> 其它指令主键列表 | D9: =IF(VLOOKUP($B9,augment_header!$B$2:$G$72,3,FALSE)="√","√","") -> √ | E9: =IF(VLOOKUP($B9,augment_header!$B$2:$G$72,4,FALSE)="√","√","") | F9: =_xlfn.LET(_xlpm.x,VLOOKUP($B9,augment_header!$B$2:$G$72,5,FALSE),IF(_xlpm.x="","",_xlpm.x))
A10: 8 | B10: mAugmentTags | C10: =_xlfn.LET(_xlpm.x,VLOOKUP($B10,augment_header!$B$2:$G$72,2,FALSE),IF(_xlpm.x="","",_xlpm.x)) -> 强化符文标签 | D10: =IF(VLOOKUP($B10,augment_header!$B$2:$G$72,3,FALSE)="√","√","") -> √ | E10: =IF(VLOOKUP($B10,augment_header!$B$2:$G$72,4,FALSE)="√","√","") -> √ | F10: =_xlfn.LET(_xlpm.x,VLOOKUP($B10,augment_header!$B$2:$G$72,5,FALSE),IF(_xlpm.x="","",_xlpm.x))
A11: 9 | B11: mBuildTags | C11: =_xlfn.LET(_xlpm.x,VLOOKUP($B11,augment_header!$B$2:$G$72,2,FALSE),IF(_xlpm.x="","",_xlpm.x)) -> 构建标签 | D11: =IF(VLOOKUP($B11,augment_header!$B$2:$G$72,3,FALSE)="√","√","") -> √ | E11: =IF(VLOOKUP($B11,augment_header!$B$2:$G$72,4,FALSE)="√","√","") -> √ | F11: =_xlfn.LET(_xlpm.x,VLOOKUP($B11,augment_header!$B$2:$G$72,5,FALSE),IF(_xlpm.x="","",_xlpm.x)) | G11: 8
